File: data_plotting/rheology/PureEG_1_1.txt
Flow ramp - 1
Stress	Shear rate	Viscosity	Step time	Temperature	Normal stress
Pa	1/s	Pa.s	s	°C	Pa
-1.15027	13.2906	-0.086548	0.466062	23.498	139.504
1.03743	31.0867	0.0333721	1.50736	23.504	139.401
1.36812	50.7362	0.0269654	2.4904	23.502	141.266
1.7274	71.7037	0.0240908	3.53898	23.499	141.194
2.06658	91.3606	0.02262	4.52202	23.502	142.854
2.39926	111.022	0.0216107	5.50506	23.501	143.766
2.725	130.678	0.0208528	6.4881	23.497	146.945
3.06674	150.334	0.0203995	7.47114	23.495	143.839
3.41609	171.311	0.0199408	8.51971	23.507	145.41
3.7566	190.96	0.0196722	9.50275	23.497	143.28
4.08163	210.625	0.0193786	10.4858	23.498	142.217
4.44495	231.587	0.0191934	11.5344	23.503	138.299
4.7751	251.238	0.0190063	12.5174	23.502	138.233
5.10569	270.909	0.0188465	13.5004	23.5	139.498
5.44075	290.555	0.0187253	14.4835	23.497	139.797
5.77471	310.221	0.0186148	15.4665	23.498	139.762
6.12699	331.19	0.0184999	16.5151	23.499	142.878
6.46081	350.847	0.0184149	17.4981	23.502	144.96
6.79202	370.505	0.0183318	18.4812	23.503	144.352
7.14499	391.473	0.0182516	19.5298	23.501	145.34
7.47577	411.13	0.0181834	20.5128	23.509	143.608
7.80771	430.787	0.0181243	21.4958	23.506	140.549
8.13826	450.445	0.0180672	22.4789	23.497	138.466
8.46578	470.091	0.0180088	23.4619	23.5	134.7
8.81534	491.069	0.0179513	24.5105	23.5	132.29
9.14692	510.728	0.0179096	25.4935	23.499	133.518
9.46909	530.388	0.0178532	26.4766	23.496	135.083
9.82577	551.353	0.0178212	27.5252	23.505	136.01
10.1472	571.012	0.0177706	28.5082	23.511	139.204
10.4795	590.67	0.0177417	29.4912	23.498	141.983
10.8283	611.636	0.0177038	30.5398	23.498	142.06
11.1478	631.294	0.0176586	31.5228	23.494	143.497
11.4752	650.932	0.0176288	32.5059	23.498	140.25
11.8017	670.611	0.0175985	33.4889	23.502	134.638
12.1246	690.267	0.0175652	34.472	23.504	131.76
12.4703	711.235	0.0175333	35.5205	23.506	128.418
12.795	730.893	0.017506	36.5036	23.508	127.264
13.1126	750.551	0.0174706	37.4866	23.5	126.303
13.4574	771.516	0.0174428	38.5352	23.498	129.527
13.777	791.176	0.0174133	39.5182	23.502	134.814
14.1002	810.834	0.0173897	40.5013	23.504	135.522
14.4189	830.492	0.0173619	41.4843	23.496	140.448
14.7381	850.147	0.017336	42.4674	23.497	138.266
15.0806	871.119	0.0173118	43.5159	23.499	137.829
15.3973	890.775	0.0172853	44.499	23.505	134.481
15.7196	910.432	0.0172661	45.482	23.496	128.321
16.0543	931.397	0.0172368	46.5306	23.497	126.682
16.3687	951.062	0.017211	47.5136	23.498	122.371
16.689	970.714	0.0171925	48.4967	23.505	119.877
17.0044	990.371	0.0171697	49.4797	23.503	119.016
17.322	1010.03	0.01715	50.4628	23.5	120.412
17.6594	1031	0.0171284	51.5113	23.494	126.74
17.9754	1050.66	0.0171088	52.4944	23.497	124.266
18.2893	1070.31	0.0170877	53.4774	23.501	130.589
18.6259	1091.28	0.0170679	54.526	23.505	135.655
18.9418	1110.94	0.0170503	55.509	23.498	131.529
19.2587	1130.59	0.0170341	56.4921	23.491	127.916
19.5938	1151.57	0.0170149	57.5406	23.496	120.922
19.9073	1171.22	0.0169971	58.5237	23.499	120.143
20.2189	1190.88	0.0169781	59.5067	23.508	109.45
20.5423	1210.49	0.0169702	60.4898	23.51	106.908
20.8404	1230.21	0.0169406	61.4728	23.503	105.687
21.1935	1251.14	0.0169393	62.5214	23.499	110.024
21.4985	1270.82	0.016917	63.5044	23.498	114.957
21.8146	1290.48	0.0169043	64.4875	23.5	120.711
22.1463	1311.45	0.016887	65.536	23.504	120.478
22.4611	1331.11	0.016874	66.5191	23.498	121.568
22.7722	1350.76	0.0168588	67.5021	23.501	119.575
23.0816	1370.42	0.0168428	68.4852	23.503	118.343
23.3981	1390.08	0.0168323	69.4682	23.504	105.684
23.7301	1411.04	0.0168174	70.5168	23.505	101.646
24.0417	1430.7	0.0168041	71.4998	23.507	100.887
24.3558	1450.36	0.016793	72.4828	23.498	95.9869
24.6847	1471.33	0.0167772	73.5314	23.496	95.3335
24.9894	1490.99	0.0167603	74.5145	23.494	99.8647
25.2819	1510.65	0.0167358	75.4975	23.502	97.6482
25.5413	1530.31	0.0166903	76.4805	23.502	92.7796
25.8009	1549.96	0.0166461	77.4636	23.502	106.502
26.1098	1570.93	0.0166206	78.5122	23.509	104.782
26.4077	1590.58	0.0166025	79.4952	23.5	96.738
26.7096	1610.24	0.0165873	80.4782	23.493	98.0914
27.0316	1631.21	0.0165715	81.5268	23.495	93.2617
27.3342	1650.87	0.0165575	82.5099	23.499	83.1132
27.6345	1670.52	0.0165424	83.4929	23.498	80.553
27.9325	1690.18	0.0165263	84.4759	23.497	76.8511
28.2363	1709.84	0.016514	85.459	23.498	80.3359
28.5623	1730.81	0.0165023	86.5076	23.501	75.6922
28.8636	1750.46	0.0164891	87.4906	23.499	79.8451
29.1615	1770.12	0.0164743	88.4736	23.506	82.5064
29.4854	1791.09	0.0164623	89.5222	23.512	95.6887
29.7908	1810.75	0.0164522	90.5052	23.51	81.7333
30.0984	1830.41	0.0164436	91.4883	23.499	83.5712
30.4227	1851.37	0.0164325	92.5369	23.498	86.6068
30.722	1871.03	0.0164198	93.5199	23.502	78.1677
31.0228	1890.69	0.0164082	94.5029	23.495	64.2281
31.3223	1910.35	0.0163961	95.486	23.505	60.1759
31.624	1930	0.0163855	96.469	23.501	61.8443
31.9429	1950.97	0.0163728	97.5176	23.502	60.3257
32.2452	1970.63	0.0163629	98.5006	23.506	62.8872
32.5476	1990.29	0.0163532	99.4837	23.499	61.6447
32.8648	2011.25	0.0163404	100.532	23.499	65.1023
33.1626	2030.91	0.0163289	101.515	23.499	70.4919
33.4598	2050.57	0.0163173	102.498	23.5	74.5196
33.7575	2070.23	0.0163062	103.481	23.497	66.0416
34.0586	2089.89	0.0162969	104.464	23.503	58.9665
34.376	2110.85	0.0162854	105.513	23.501	56.3475
34.6739	2130.51	0.0162749	106.496	23.5	52.958
34.9693	2150.17	0.0162635	107.479	23.503	37.8969
35.2845	2171.14	0.0162516	108.528	23.502	39.546
35.5873	2190.77	0.0162442	109.511	23.495	42.8676
35.8861	2210.42	0.016235	110.494	23.501	42.5232
36.1627	2230.09	0.0162158	111.477	23.499	39.7565
36.4738	2249.77	0.0162123	112.46	23.506	50.1465
36.7919	2270.73	0.0162027	113.508	23.504	45.5945
37.0926	2290.39	0.0161949	114.491	23.496	48.8911
37.3859	2310.05	0.016184	115.474	23.494	50.4007
37.6963	2331.02	0.0161716	116.523	23.494	34.7748
37.9937	2350.67	0.0161629	117.506	23.496	31.8092
38.287	2370.33	0.0161526	118.489	23.496	24.0461
38.6006	2391.3	0.0161421	119.538	23.502	13.9989
38.8979	2410.96	0.0161338	120.521	23.501	16.088
39.1919	2430.62	0.0161243	121.504	23.498	21.1038
39.484	2450.27	0.0161141	122.487	23.5	20.3449
39.7715	2469.93	0.0161023	123.47	23.498	21.8566
40.0828	2490.9	0.0160917	124.518	23.502	28.7005
40.3748	2510.56	0.016082	125.501	23.502	27.7492
40.6668	2530.21	0.0160725	126.485	23.504	28.3635
40.9744	2551.18	0.016061	127.533	23.502	30.4239
41.2647	2570.84	0.0160511	128.516	23.493	13.6734
41.5529	2590.5	0.0160405	129.499	23.496	9.99788
41.8465	2610.15	0.0160322	130.482	23.498	0.680851
42.1377	2629.81	0.0160231	131.465	23.5	-10.3902
42.4447	2650.78	0.0160122	132.514	23.504	-0.986583
42.7296	2670.44	0.016001	133.497	23.499	-17.9562
43.0172	2690.1	0.015991	134.48	23.5	6.77251
43.3286	2711.06	0.0159821	135.528	23.502	-7.62401
43.6169	2730.72	0.0159726	136.512	23.502	-27.6972
43.904	2750.38	0.0159629	137.495	23.506	-21.9955
44.1925	2770.04	0.0159538	138.478	23.498	8.10429
44.4839	2789.69	0.0159458	139.461	23.497	11.2698
44.7938	2810.66	0.0159371	140.509	23.5	-12.8218
45.0734	2830.32	0.0159252	141.492	23.493	-18.5304
45.3528	2849.98	0.0159134	142.475	23.494	-30.5537
45.6622	2870.94	0.0159049	143.524	23.5	-31.7057
45.9529	2890.6	0.0158973	144.507	23.495	-37.3609
46.2328	2910.26	0.0158861	145.49	23.497	-38.6505
46.5515	2931.15	0.0158817	146.539	23.504	-32.2393
46.8006	2950.87	0.0158599	147.522	23.502	-31.1136
47.0948	2970.54	0.0158539	148.505	23.497	-23.3365
47.3752	2990.2	0.0158435	149.488	23.503	-23.7127
47.6654	3009.86	0.0158364	150.471	23.504	-20.6014
47.9644	3030.83	0.0158255	151.519	23.501	-27.2631
48.2517	3050.48	0.0158177	152.502	23.497	-29.0649
48.5342	3070.14	0.0158084	153.485	23.503	-46.3246
48.8326	3091.11	0.0157977	154.534	23.501	-49.7981
49.1117	3110.77	0.0157876	155.517	23.495	-74.1043
49.3845	3130.42	0.0157757	156.5	23.497	-77.8915
49.6661	3150.08	0.0157666	157.483	23.505	-70.138
49.9604	3169.74	0.0157617	158.466	23.506	-61.0255
50.257	3190.71	0.015751	159.515	23.501	-63.9412
50.524	3210.37	0.0157378	160.498	23.501	-57.2348
50.8048	3230.02	0.0157289	161.481	23.511	-47.4865
51.1064	3250.99	0.0157203	162.529	23.506	-60.2104
51.3894	3270.65	0.0157123	163.512	23.501	-55.5904
51.6684	3290.31	0.0157032	164.495	23.497	-63.5716
51.9448	3309.96	0.0156935	165.478	23.5	-71.9585
52.2203	3329.62	0.0156836	166.461	23.502	-93.9219
52.5201	3350.59	0.0156749	167.51	23.499	-99.8976
52.7894	3370.25	0.0156634	168.493	23.5	-95.424
53.0563	3389.91	0.0156513	169.476	23.499	-96.1129
53.3531	3410.87	0.0156421	170.525	23.505	-108.891
53.6332	3430.53	0.0156341	171.508	23.507	-114.314
53.9171	3450.19	0.0156273	172.491	23.506	-89.118
54.2094	3471.16	0.0156171	173.539	23.504	-78.3605
54.4813	3490.81	0.0156071	174.522	23.496	-94.3884
54.7527	3510.47	0.015597	175.505	23.492	-99.4248
55.0245	3530.13	0.0155871	176.488	23.493	-104.209
55.2988	3549.79	0.0155781	177.472	23.497	-110.106
55.5868	3570.75	0.0155672	178.52	23.504	-116.924
55.8679	3590.41	0.0155603	179.503	23.505	-142.294
56.1555	3610.07	0.0155552	180.486	23.501	-130.432
56.466	3631.03	0.0155509	181.535	23.504	-110.372
56.7399	3650.7	0.0155422	182.518	23.504	-105.469
56.991	3670.25	0.0155278	183.501	23.494	-103.293
57.2489	3690	0.0155146	184.484	23.495	-117.175
57.5091	3709.67	0.0155025	185.467	23.498	-128.146
57.7991	3730.63	0.0154931	186.515	23.502	-122.978
58.0834	3750.29	0.0154877	187.499	23.499	-122.498
58.3478	3769.95	0.0154771	188.482	23.5	-143.511
58.6362	3790.92	0.0154675	189.53	23.498	-153.189
58.9036	3810.58	0.0154579	190.513	23.497	-158.069
59.1691	3830.23	0.0154479	191.496	23.499	-165.184
59.4481	3849.89	0.0154415	192.479	23.509	-168.254
59.7223	3869.55	0.0154339	193.462	23.505	-179.318
60.0085	3890.52	0.0154243	194.511	23.505	-163.297
60.2723	3910.17	0.0154142	195.494	23.501	-164.556
60.5367	3929.83	0.0154044	196.477	23.497	-151.939
60.8152	3950.8	0.0153931	197.526	23.5	-163.846
61.0815	3970.46	0.015384	198.509	23.5	-158.961
61.3549	3990.11	0.0153767	199.492	23.502	-167.109
61.6417	4011.08	0.0153679	200.54	23.498	-184.877
61.9046	4030.74	0.0153581	201.523	23.501	-177.842
62.164	4050.4	0.0153476	202.506	23.499	-191.122
62.4212	4070.06	0.0153367	203.489	23.5	-220.077
62.6947	4089.71	0.0153298	204.472	23.498	-235.524
62.9762	4110.68	0.0153201	205.521	23.493	-227.61
63.2379	4130.34	0.0153106	206.504	23.49	-235.549
63.4911	4150	0.0152991	207.487	23.502	-204.985
63.7705	4170.97	0.0152892	208.536	23.501	-195.36
64.0354	4190.62	0.0152806	209.519	23.503	-198.76
64.297	4210.28	0.0152714	210.502	23.502	-197.708
64.5702	4229.94	0.0152651	211.485	23.5	-206.791
64.8234	4249.6	0.015254	212.468	23.498	-218.368
65.0996	4270.56	0.0152438	213.516	23.497	-228.697
65.3589	4290.22	0.0152344	214.499	23.503	-233.818
65.6211	4309.88	0.0152257	215.482	23.502	-240.911
65.8989	4330.85	0.0152162	216.531	23.501	-257.753
66.1498	4350.51	0.0152051	217.514	23.503	-246.755
66.4018	4370.16	0.0151944	218.497	23.501	-262.102
66.6544	4389.82	0.0151838	219.48	23.5	-248.343
66.9167	4409.34	0.0151761	220.463	23.497	-249.956
67.1636	4430.45	0.0151595	221.512	23.502	-244.867
67.4487	4450.09	0.0151567	222.495	23.508	-240.058
67.7015	4469.76	0.0151466	223.478	23.504	-250.77
67.9855	4490.73	0.0151391	224.526	23.5	-255.186
68.2343	4510.39	0.0151283	225.509	23.495	-277.727
68.477	4530.04	0.0151162	226.492	23.502	-300.918
68.7507	4551.01	0.0151067	227.541	23.499	-276.677
69.0127	4570.67	0.015099	228.524	23.501	-284.879
69.2664	4590.32	0.0150897	229.507	23.505	-303.408
69.5225	4609.99	0.0150809	230.49	23.499	-315.636
69.7629	4629.64	0.0150687	231.473	23.501	-280.712
70.0335	4650.61	0.015059	232.522	23.502	-282.779
70.277	4670.27	0.0150477	233.505	23.497	-293.802
70.5325	4689.92	0.0150392	234.488	23.5	-278.178
70.8052	4710.89	0.0150301	235.536	23.497	-292.636
71.052	4730.55	0.0150198	236.519	23.502	-309.492
71.2918	4750.21	0.0150081	237.503	23.503	-322.55
71.5435	4769.87	0.0149991	238.486	23.503	-331.009
71.8064	4789.52	0.0149924	239.469	23.506	-336.925
72.0773	4810.49	0.0149834	240.517	23.497	-333.391
72.3168	4830.15	0.014972	241.5	23.491	-355.484
72.5583	4849.81	0.0149611	242.483	23.495	-343.936
72.813	4870.78	0.0149489	243.532	23.501	-327.945
73.0632	4890.43	0.01494	244.515	23.5	-337.687
73.3208	4910.09	0.0149327	245.498	23.5	-333.445
73.5771	4929.75	0.0149251	246.481	23.506	-335.462
73.8347	4949.4	0.0149179	247.464	23.496	-338.801
74.0931	4970.38	0.0149069	248.513	23.5	-358.168
74.3325	4990.03	0.0148962	249.496	23.501	-364.933
74.5723	5009.68	0.0148856	250.479	23.507	-386.769
74.8448	5030.66	0.0148777	251.527	23.508	-387.083
75.0834	5050.32	0.0148671	252.51	23.498	-403.995
75.3286	5069.97	0.0148578	253.493	23.498	-383.555
75.5561	5089.63	0.0148451	254.476	23.496	-385.974
75.792	5109.28	0.0148342	255.459	23.5	-382.981
76.082	5130.11	0.0148305	256.508	23.506	-387.879
76.3079	5149.99	0.0148171	257.491	23.503	-392.075
76.5268	5169.47	0.0148036	258.474	23.5	-379.257
76.8059	5190.54	0.0147973	259.523	23.507	-389.872
77.0643	5210.19	0.0147911	260.506	23.503	-405.468
77.2992	5229.86	0.0147804	261.489	23.491	-423.504
77.5581	5250.81	0.0147707	262.537	23.493	-433.681
77.8057	5270.48	0.0147625	263.52	23.499	-448.596
78.0308	5290.13	0.0147503	264.503	23.499	-445.628
78.2949	5309.79	0.0147454	265.486	23.501	-452.455
78.5369	5329.45	0.0147364	266.469	23.502	-443.203
78.793	5350.42	0.0147265	267.518	23.501	-435.686
79.038	5370.07	0.0147182	268.501	23.505	-431.864
79.2587	5389.73	0.0147055	269.484	23.499	-455.783
79.5245	5410.7	0.0146976	270.533	23.498	-406.318
79.7773	5430.36	0.014691	271.516	23.502	-465.096
80.0198	5450.02	0.0146825	272.499	23.497	-484.424
80.2569	5469.67	0.0146731	273.482	23.496	-476.299
80.489	5489.33	0.0146628	274.465	23.5	-498.4
80.7463	5510.3	0.0146537	275.513	23.505	-525.796
80.9802	5529.96	0.0146439	276.496	23.5	-490.78
81.2291	5549.61	0.0146369	277.479	23.5	-504.37
81.4957	5570.59	0.0146296	278.528	23.499	-500.791
81.7265	5590.24	0.0146195	279.511	23.503	-486.551
81.9695	5609.9	0.0146116	280.494	23.505	-485.016
82.1901	5629.56	0.0145997	281.477	23.504	-497.233
82.4231	5649.21	0.0145902	282.46	23.503	-480.44
82.674	5670.19	0.0145805	283.509	23.498	-511.184
82.9083	5689.83	0.0145713	284.492	23.498	-520.259
83.13	5709.5	0.0145599	285.475	23.499	-536.831
83.3873	5730.46	0.0145516	286.523	23.5	-541.458
83.6184	5750.12	0.014542	287.506	23.503	-558.932
83.869	5769.77	0.0145359	288.49	23.499	-554.044
84.139	5790.75	0.0145299	289.538	23.5	-553.054
84.3636	5810.41	0.0145194	290.521	23.495	-564.078
84.5867	5830.06	0.0145087	291.504	23.498	-555.993
84.8127	5849.72	0.0144986	292.487	23.506	-541.185
85.0474	5869.38	0.01449	293.47	23.504	-545.02
85.3235	5890.34	0.0144853	294.519	23.498	-550.026
85.5493	5910.01	0.0144753	295.502	23.492	-563.225
85.7599	5929.67	0.0144628	296.485	23.497	-577.096
85.9932	5950.63	0.0144511	297.533	23.5	-591.754
86.2218	5970.29	0.0144418	298.517	23.499	-606.337
86.411	5987.33	0.0144323	299.368	23.5	-609.583